Traceback (most recent call last):
  File "/home/runner/micromamba/envs/comp2421-book/lib/python3.12/site-packages/jupyter_cache/executors/utils.py", line 58, in single_nb_execution
    executenb(
  File "/home/runner/micromamba/envs/comp2421-book/lib/python3.12/site-packages/nbclient/client.py", line 1305, in execute
    return NotebookClient(nb=nb, resources=resources, km=km, **kwargs).execute()
           ^^^^^^^^^^^^^^^^^^^^^^^^^^^^^^^^^^^^^^^^^^^^^^^^^^^^^^^^^^^^^^^^^^^^^
  File "/home/runner/micromamba/envs/comp2421-book/lib/python3.12/site-packages/jupyter_core/utils/__init__.py", line 165, in wrapped
    return loop.run_until_complete(inner)
           ^^^^^^^^^^^^^^^^^^^^^^^^^^^^^^
  File "/home/runner/micromamba/envs/comp2421-book/lib/python3.12/asyncio/base_events.py", line 687, in run_until_complete
    return future.result()
           ^^^^^^^^^^^^^^^
  File "/home/runner/micromamba/envs/comp2421-book/lib/python3.12/site-packages/nbclient/client.py", line 705, in async_execute
    await self.async_execute_cell(
  File "/home/runner/micromamba/envs/comp2421-book/lib/python3.12/site-packages/nbclient/client.py", line 1058, in async_execute_cell
    await self._check_raise_for_error(cell, cell_index, exec_reply)
  File "/home/runner/micromamba/envs/comp2421-book/lib/python3.12/site-packages/nbclient/client.py", line 914, in _check_raise_for_error
    raise CellExecutionError.from_cell_and_msg(cell, exec_reply_content)
nbclient.exceptions.CellExecutionError: An error occurred while executing the following cell:
------------------
from datetime import datetime as dt
import pandas as pd
import requests
from io import BytesIO

data_url = "http://www.ons.gov.uk/file?uri=/employmentandlabourmarket/peopleinwork/earningsandworkinghours/datasets/averageweeklyearningsearn01/current/earn01nov2024.xls"
r = requests.get(data_url)
df = pd.read_excel(BytesIO(r.content), sheet_name="1. AWE Total Pay")
df = df.iloc[:, [0, 1]]
df.columns = ["date", "earnings"]
df = df.dropna()
# since 2008
df = df[df["date"] > dt("2008-01-01")]


def to_days(date):
    return float((date - dt(2008, 1, 1)).days)


days = df.apply(lambda row: to_days(row.date), axis=1)
------------------


[0;31m---------------------------------------------------------------------------[0m
[0;31mTypeError[0m                                 Traceback (most recent call last)
Cell [0;32mIn[1], line 13[0m
[1;32m     11[0m df [38;5;241m=[39m df[38;5;241m.[39mdropna()
[1;32m     12[0m [38;5;66;03m# since 2008[39;00m
[0;32m---> 13[0m df [38;5;241m=[39m df[df[[38;5;124m"[39m[38;5;124mdate[39m[38;5;124m"[39m] [38;5;241m>[39m [43mdt[49m[43m([49m[38;5;124;43m"[39;49m[38;5;124;43m2008-01-01[39;49m[38;5;124;43m"[39;49m[43m)[49m]
[1;32m     16[0m [38;5;28;01mdef[39;00m [38;5;21mto_days[39m(date):
[1;32m     17[0m     [38;5;28;01mreturn[39;00m [38;5;28mfloat[39m((date [38;5;241m-[39m dt([38;5;241m2008[39m, [38;5;241m1[39m, [38;5;241m1[39m))[38;5;241m.[39mdays)

[0;31mTypeError[0m: 'str' object cannot be interpreted as an integer

